[2023-07-02 05:42:19,222][mylib.train][INFO] - Instantiating datamodule <mylib.data.cifar_datamodule.CIFARDataModule>
[2023-07-02 05:42:19,226][mylib.train][INFO] - Instantiating model <mylib.model.timm_module.TIMMModule>
[2023-07-02 05:42:19,231][mylib.utils.utils][ERROR] - 
Traceback (most recent call last):
  File "/workspace/.pyenv_mirror/user/current/lib/python3.11/site-packages/hydra/_internal/utils.py", line 635, in _locate
    obj = import_module(part0)
          ^^^^^^^^^^^^^^^^^^^^
  File "/home/gitpod/.pyenv/versions/3.11.1/lib/python3.11/importlib/__init__.py", line 126, in import_module
    return _bootstrap._gcd_import(name[level:], package, level)
           ^^^^^^^^^^^^^^^^^^^^^^^^^^^^^^^^^^^^^^^^^^^^^^^^^^^^
  File "<frozen importlib._bootstrap>", line 1206, in _gcd_import
  File "<frozen importlib._bootstrap>", line 1178, in _find_and_load
  File "<frozen importlib._bootstrap>", line 1142, in _find_and_load_unlocked
ModuleNotFoundError: No module named 'timm'

The above exception was the direct cause of the following exception:

Traceback (most recent call last):
  File "/workspace/.pyenv_mirror/user/current/lib/python3.11/site-packages/hydra/_internal/instantiate/_instantiate2.py", line 134, in _resolve_target
    target = _locate(target)
             ^^^^^^^^^^^^^^^
  File "/workspace/.pyenv_mirror/user/current/lib/python3.11/site-packages/hydra/_internal/utils.py", line 637, in _locate
    raise ImportError(
ImportError: Error loading 'timm.create_model':
ModuleNotFoundError("No module named 'timm'")
Are you sure that module 'timm' is installed?

The above exception was the direct cause of the following exception:

Traceback (most recent call last):
  File "/workspace/EMLO/mylib/utils/utils.py", line 65, in wrap
    metric_dict, object_dict = task_func(cfg=cfg)
                               ^^^^^^^^^^^^^^^^^^
  File "/workspace/EMLO/mylib/train.py", line 23, in train
    model: LightningModule = hydra.utils.instantiate(cfg.model)
                             ^^^^^^^^^^^^^^^^^^^^^^^^^^^^^^^^^^
  File "/workspace/.pyenv_mirror/user/current/lib/python3.11/site-packages/hydra/_internal/instantiate/_instantiate2.py", line 226, in instantiate
    return instantiate_node(
           ^^^^^^^^^^^^^^^^^
  File "/workspace/.pyenv_mirror/user/current/lib/python3.11/site-packages/hydra/_internal/instantiate/_instantiate2.py", line 342, in instantiate_node
    value = instantiate_node(
            ^^^^^^^^^^^^^^^^^
  File "/workspace/.pyenv_mirror/user/current/lib/python3.11/site-packages/hydra/_internal/instantiate/_instantiate2.py", line 333, in instantiate_node
    _target_ = _resolve_target(node.get(_Keys.TARGET), full_key)
               ^^^^^^^^^^^^^^^^^^^^^^^^^^^^^^^^^^^^^^^^^^^^^^^^^
  File "/workspace/.pyenv_mirror/user/current/lib/python3.11/site-packages/hydra/_internal/instantiate/_instantiate2.py", line 139, in _resolve_target
    raise InstantiationException(msg) from e
hydra.errors.InstantiationException: Error locating target 'timm.create_model', set env var HYDRA_FULL_ERROR=1 to see chained exception.
full_key: model.net
[2023-07-02 05:42:19,233][mylib.utils.utils][INFO] - Output dir: /workspace/EMLO/outputs/2023-07-02/05-42-19
