[2023-07-01 19:56:45,389][__main__][INFO] - Instantiating datamodule <mylib.data.cifar_module.CIFARDataModule>
[2023-07-01 19:56:45,391][mylib.utils.utils][ERROR] - 
Traceback (most recent call last):
  File "/workspace/.pyenv_mirror/user/current/lib/python3.11/site-packages/hydra/_internal/utils.py", line 644, in _locate
    obj = getattr(obj, part)
          ^^^^^^^^^^^^^^^^^^
AttributeError: module 'mylib.data' has no attribute 'cifar_module'

During handling of the above exception, another exception occurred:

Traceback (most recent call last):
  File "/workspace/.pyenv_mirror/user/current/lib/python3.11/site-packages/hydra/_internal/utils.py", line 650, in _locate
    obj = import_module(mod)
          ^^^^^^^^^^^^^^^^^^
  File "/home/gitpod/.pyenv/versions/3.11.1/lib/python3.11/importlib/__init__.py", line 126, in import_module
    return _bootstrap._gcd_import(name[level:], package, level)
           ^^^^^^^^^^^^^^^^^^^^^^^^^^^^^^^^^^^^^^^^^^^^^^^^^^^^
  File "<frozen importlib._bootstrap>", line 1206, in _gcd_import
  File "<frozen importlib._bootstrap>", line 1178, in _find_and_load
  File "<frozen importlib._bootstrap>", line 1142, in _find_and_load_unlocked
ModuleNotFoundError: No module named 'mylib.data.cifar_module'

The above exception was the direct cause of the following exception:

Traceback (most recent call last):
  File "/workspace/.pyenv_mirror/user/current/lib/python3.11/site-packages/hydra/_internal/instantiate/_instantiate2.py", line 134, in _resolve_target
    target = _locate(target)
             ^^^^^^^^^^^^^^^
  File "/workspace/.pyenv_mirror/user/current/lib/python3.11/site-packages/hydra/_internal/utils.py", line 653, in _locate
    raise ImportError(
ImportError: Error loading 'mylib.data.cifar_module.CIFARDataModule':
ModuleNotFoundError("No module named 'mylib.data.cifar_module'")
Are you sure that 'cifar_module' is importable from module 'mylib.data'?

The above exception was the direct cause of the following exception:

Traceback (most recent call last):
  File "/workspace/EMLO/mylib/utils/utils.py", line 65, in wrap
    metric_dict, object_dict = task_func(cfg=cfg)
                               ^^^^^^^^^^^^^^^^^^
  File "/workspace/EMLO/mylib/train.py", line 20, in train
    datamodule: LightningDataModule = hydra.utils.instantiate(cfg.data)
                                      ^^^^^^^^^^^^^^^^^^^^^^^^^^^^^^^^^
  File "/workspace/.pyenv_mirror/user/current/lib/python3.11/site-packages/hydra/_internal/instantiate/_instantiate2.py", line 226, in instantiate
    return instantiate_node(
           ^^^^^^^^^^^^^^^^^
  File "/workspace/.pyenv_mirror/user/current/lib/python3.11/site-packages/hydra/_internal/instantiate/_instantiate2.py", line 333, in instantiate_node
    _target_ = _resolve_target(node.get(_Keys.TARGET), full_key)
               ^^^^^^^^^^^^^^^^^^^^^^^^^^^^^^^^^^^^^^^^^^^^^^^^^
  File "/workspace/.pyenv_mirror/user/current/lib/python3.11/site-packages/hydra/_internal/instantiate/_instantiate2.py", line 139, in _resolve_target
    raise InstantiationException(msg) from e
hydra.errors.InstantiationException: Error locating target 'mylib.data.cifar_module.CIFARDataModule', set env var HYDRA_FULL_ERROR=1 to see chained exception.
full_key: data
[2023-07-01 19:56:45,393][mylib.utils.utils][INFO] - Output dir: /workspace/EMLO/mylib/outputs/2023-07-01/19-56-45
